<?xml version="1.0" encoding="UTF-8"?>
<testng-results skipped="0" failed="1" ignored="0" total="3" passed="2">
  <reporter-output>
  </reporter-output>
  <suite name="Default suite" duration-ms="223" started-at="2021-03-31T09:06:43Z" finished-at="2021-03-31T09:06:43Z">
    <groups>
    </groups>
    <test name="Default test" duration-ms="223" started-at="2021-03-31T09:06:43Z" finished-at="2021-03-31T09:06:43Z">
      <class name="MavenPractice.MavenPracticeTest.testClass">
        <test-method status="PASS" signature="diff()[pri:0, instance:MavenPractice.MavenPracticeTest.testClass@7823a2f9]" name="diff" duration-ms="52" started-at="2021-03-31T09:06:43Z" finished-at="2021-03-31T09:06:43Z">
          <reporter-output>
          </reporter-output>
        </test-method> <!-- diff -->
        <test-method status="FAIL" signature="div()[pri:0, instance:MavenPractice.MavenPracticeTest.testClass@7823a2f9]" name="div" duration-ms="16" started-at="2021-03-31T09:06:43Z" finished-at="2021-03-31T09:06:43Z">
          <exception class="java.lang.AssertionError">
            <message>
              <![CDATA[expected [10] but found [9]]]>
            </message>
            <full-stacktrace>
              <![CDATA[java.lang.AssertionError: expected [10] but found [9]
at org.testng.Assert.fail(Assert.java:96)
at org.testng.Assert.failNotEquals(Assert.java:776)
at org.testng.Assert.assertEqualsImpl(Assert.java:137)
at org.testng.Assert.assertEquals(Assert.java:118)
at org.testng.Assert.assertEquals(Assert.java:652)
at org.testng.Assert.assertEquals(Assert.java:662)
at MavenPractice.MavenPracticeTest.testClass.div(testClass.java:26)
at sun.reflect.NativeMethodAccessorImpl.invoke0(Native Method)
at sun.reflect.NativeMethodAccessorImpl.invoke(NativeMethodAccessorImpl.java:62)
at sun.reflect.DelegatingMethodAccessorImpl.invoke(DelegatingMethodAccessorImpl.java:43)
at java.lang.reflect.Method.invoke(Method.java:498)
at org.testng.internal.MethodInvocationHelper.invokeMethod(MethodInvocationHelper.java:124)
at org.testng.internal.Invoker.invokeMethod(Invoker.java:583)
at org.testng.internal.Invoker.invokeTestMethod(Invoker.java:719)
at org.testng.internal.Invoker.invokeTestMethods(Invoker.java:989)
at org.testng.internal.TestMethodWorker.invokeTestMethods(TestMethodWorker.java:125)
at org.testng.internal.TestMethodWorker.run(TestMethodWorker.java:109)
at org.testng.TestRunner.privateRun(TestRunner.java:648)
at org.testng.TestRunner.run(TestRunner.java:505)
at org.testng.SuiteRunner.runTest(SuiteRunner.java:455)
at org.testng.SuiteRunner.runSequentially(SuiteRunner.java:450)
at org.testng.SuiteRunner.privateRun(SuiteRunner.java:415)
at org.testng.SuiteRunner.run(SuiteRunner.java:364)
at org.testng.SuiteRunnerWorker.runSuite(SuiteRunnerWorker.java:52)
at org.testng.SuiteRunnerWorker.run(SuiteRunnerWorker.java:84)
at org.testng.TestNG.runSuitesSequentially(TestNG.java:1208)
at org.testng.TestNG.runSuitesLocally(TestNG.java:1137)
at org.testng.TestNG.runSuites(TestNG.java:1049)
at org.testng.TestNG.run(TestNG.java:1017)
at org.testng.remote.AbstractRemoteTestNG.run(AbstractRemoteTestNG.java:114)
at org.testng.remote.RemoteTestNG.initAndRun(RemoteTestNG.java:251)
at org.testng.remote.RemoteTestNG.main(RemoteTestNG.java:77)
]]>
            </full-stacktrace>
          </exception> <!-- java.lang.AssertionError -->
          <reporter-output>
          </reporter-output>
        </test-method> <!-- div -->
        <test-method status="PASS" signature="sum()[pri:0, instance:MavenPractice.MavenPracticeTest.testClass@7823a2f9]" name="sum" duration-ms="15" started-at="2021-03-31T09:06:43Z" finished-at="2021-03-31T09:06:43Z">
          <reporter-output>
          </reporter-output>
        </test-method> <!-- sum -->
      </class> <!-- MavenPractice.MavenPracticeTest.testClass -->
    </test> <!-- Default test -->
  </suite> <!-- Default suite -->
</testng-results>
